Workbook

Sheet คู่มือการใช้งาน
A1: แบบบันทึกผลการทดลอง — โปรเจกต์หุ่นยนต์ดูดฝุ่น
A3: วิธีใช้ไฟล์นี้
A4: • | B4: ไฟล์นี้มี 1 แท็บต่อ 1 หัวข้อทดสอบ ตรงกับแผนงานในไฟล์ project_next_steps_plan.md (หัวข้อ 1.1–1.5)
A5: • | B5: กรอกข้อมูลเฉพาะช่องสีเหลือง (Input) เท่านั้น — ห้ามแก้ช่องสีขาว/เทาเพราะมีสูตรคำนวณอยู่
A6: • | B6: แถวสีเทาตัวเอียงบนสุดของแต่ละตารางคือ 'แถวตัวอย่าง' แสดงรูปแบบการกรอกที่ถูกต้อง ไม่ต้องลบก็ได้ ไม่ถูกนับในค่าเฉลี่ย
A7: • | B7: คอลัมน์ผลลัพธ์/สถานะ (สีเขียว=ผ่าน, สีแดง=ไม่ผ่าน, สีเทา=รอข้อมูล) คำนวณอัตโนมัติจากข้อมูลที่กรอก ไม่ต้องกรอกเอง
A8: • | B8: แท็บ 'สรุปผลรวม' จะดึงผลจากทุกแท็บมารวมเป็นภาพรวมให้อัตโนมัติ ให้กรอกข้อมูลในแท็บย่อยก่อน แล้วดูสรุปทีหลัง
A9: • | B9: ถ้าทดลองมากกว่าจำนวนแถวที่เตรียมไว้ ให้เลือกแถวสุดท้ายของตาราง คลิกขวา > Insert > Row Above แล้วคัดลอกสูตร/สีจากแถวเหนือมันลงมา
A10: • | B10: หน่วยที่ใช้ระบุไว้ในหัวตารางทุกคอลัมน์แล้ว ให้วัดและกรอกตามหน่วยนั้น
A12: สารบัญแท็บ
A13: 1.1 มอเตอร์ดูด | B13: ทดสอบแรงดูด/กระแส/ประสิทธิภาพเก็บฝุ่น
A14: 1.2 การขับเคลื่อน | B14: odometry, ข้ามธรณีประตู, กระแสมอเตอร์ขับ, เซนเซอร์กันตก/กันชน
A15: 1.3 การปัดกวาด | B15: ประสิทธิภาพเก็บเศษของแปรงข้าง ร่วมกับมอเตอร์ดูด
A16: 1.4 Scissor Lift | B16: เวลายก/พับ, กระแสเซอร์โว, การแกว่งปลายเสา, repeatability, self-lock
A17: 1.5 ทดสอบรวมระบบ | B17: power budget, mission/safety checklist, endurance test
A18: สรุปผลรวม | B18: ภาพรวมสถานะทุกการทดสอบ ดึงข้อมูลอัตโนมัติจากแท็บอื่น

Sheet 1.1 มอเตอร์ดูด
A1: 1.1 การทดสอบมอเตอร์ดูดฝุ่น (Suction Motor Test)
A3: ข้อมูลการทดสอบ
A4: วันที่ทดสอบ: | C4: ผู้ทดสอบ:
A5: รุ่นมอเตอร์/ใบพัด: | C5: แรงดันไฟที่ใช้ (V):
A7: ตารางที่ 1: กระแสไฟและแรงดัน Manometer (Pressure & Current)
A8: Trial | B8: กระแส Free-run (A) | C8: กระแส Stall (A) | D8: แรงดัน Manometer (mmH2O) | E8: หมายเหตุ
A9: ตัวอย่าง | B9: 0.85 | C9: 2.1 | D9: 450 | E9: วัดที่ 6V, ปิดปลายท่อสนิท
A10: 1
A11: 2
A12: 3
A13: 4
A14: 5
A15: 6
A16: 7
A17: ค่าเฉลี่ย | B17: =IFERROR(AVERAGE(B10:B16),"") | C17: =IFERROR(AVERAGE(C10:C16),"") | D17: =IFERROR(AVERAGE(D10:D16),"")
A19: ตารางที่ 2: ประสิทธิภาพเก็บฝุ่น (Debris Pickup Efficiency, เกณฑ์ผ่าน ≥ 80%)
A20: Trial | B20: พื้นผิว | C20: ชนิดเศษวัสดุ | D20: น้ำหนักก่อนดูด (g) | E20: น้ำหนักเศษเหลือหลังดูด (g) | F20: % เก็บได้ | G20: ผ่านเกณฑ์
A21: ตัวอย่าง | B21: กระเบื้อง | C21: ข้าวสาร | D21: 20 | E21: 3 | F21: =IF(OR(D21="",E21=""),"",IFERROR((D21-E21)/D21,"")) -> 0.85 | G21: =IF(F21="","",IF(F21>=0.8,"ผ่าน ✓","ไม่ผ่าน ✗")) -> ผ่าน ✓
A22: 1 | F22: =IF(OR(D22="",E22=""),"",IFERROR((D22-E22)/D22,"")) | G22: =IF(F22="","",IF(F22>=0.8,"ผ่าน ✓","ไม่ผ่าน ✗"))
A23: 2 | F23: =IF(OR(D23="",E23=""),"",IFERROR((D23-E23)/D23,"")) | G23: =IF(F23="","",IF(F23>=0.8,"ผ่าน ✓","ไม่ผ่าน ✗"))
A24: 3 | F24: =IF(OR(D24="",E24=""),"",IFERROR((D24-E24)/D24,"")) | G24: =IF(F24="","",IF(F24>=0.8,"ผ่าน ✓","ไม่ผ่าน ✗"))
A25: 4 | F25: =IF(OR(D25="",E25=""),"",IFERROR((D25-E25)/D25,"")) | G25: =IF(F25="","",IF(F25>=0.8,"ผ่าน ✓","ไม่ผ่าน ✗"))
A26: 5 | F26: =IF(OR(D26="",E26=""),"",IFERROR((D26-E26)/D26,"")) | G26: =IF(F26="","",IF(F26>=0.8,"ผ่าน ✓","ไม่ผ่าน ✗"))
A27: 6 | F27: =IF(OR(D27="",E27=""),"",IFERROR((D27-E27)/D27,"")) | G27: =IF(F27="","",IF(F27>=0.8,"ผ่าน ✓","ไม่ผ่าน ✗"))
A28: 7 | F28: =IF(OR(D28="",E28=""),"",IFERROR((D28-E28)/D28,"")) | G28: =IF(F28="","",IF(F28>=0.8,"ผ่าน ✓","ไม่ผ่าน ✗"))
A29: ค่าเฉลี่ย / สรุปผล | F29: =IFERROR(AVERAGE(F22:F28),"") | G29: =IF(COUNT(F22:F28)=0,"รอข้อมูล",IF(F29>=0.8,"ผ่าน ✓","ไม่ผ่าน ✗")) -> รอข้อมูล

Sheet 1.2 การขับเคลื่อน
A1: 1.2 การทดสอบการขับเคลื่อน (Locomotion Test)
A3: ข้อมูลการทดสอบ
A4: วันที่ทดสอบ: | C4: ผู้ทดสอบ:
A6: ตารางที่ 1: ความแม่นยำ Odometry (เกณฑ์ผ่าน error < 5%)
A7: Trial | B7: ประเภท (ระยะ/มุม) | C7: ค่าที่สั่ง | D7: ค่าจริงที่วัดได้ (ตลับเมตร/องศา) | E7: ค่าที่ Encoder อ่านได้ (แปลงหน่วยเดียวกัน) | F7: % Error | G7: ผ่าน
A8: ตัวอย่าง | B8: ระยะ (mm) | C8: 1000 | D8: 1000 | E8: 985 | F8: =IF(OR(D8="",E8=""),"",IFERROR(ABS(E8-D8)/D8,"")) -> 0.015 | G8: =IF(F8="","",IF(F8<0.05,"ผ่าน ✓","ไม่ผ่าน ✗")) -> ผ่าน ✓
A9: 1 | F9: =IF(OR(D9="",E9=""),"",IFERROR(ABS(E9-D9)/D9,"")) | G9: =IF(F9="","",IF(F9<0.05,"ผ่าน ✓","ไม่ผ่าน ✗"))
A10: 2 | F10: =IF(OR(D10="",E10=""),"",IFERROR(ABS(E10-D10)/D10,"")) | G10: =IF(F10="","",IF(F10<0.05,"ผ่าน ✓","ไม่ผ่าน ✗"))
A11: 3 | F11: =IF(OR(D11="",E11=""),"",IFERROR(ABS(E11-D11)/D11,"")) | G11: =IF(F11="","",IF(F11<0.05,"ผ่าน ✓","ไม่ผ่าน ✗"))
A12: 4 | F12: =IF(OR(D12="",E12=""),"",IFERROR(ABS(E12-D12)/D12,"")) | G12: =IF(F12="","",IF(F12<0.05,"ผ่าน ✓","ไม่ผ่าน ✗"))
A13: 5 | F13: =IF(OR(D13="",E13=""),"",IFERROR(ABS(E13-D13)/D13,"")) | G13: =IF(F13="","",IF(F13<0.05,"ผ่าน ✓","ไม่ผ่าน ✗"))
A14: 6 | F14: =IF(OR(D14="",E14=""),"",IFERROR(ABS(E14-D14)/D14,"")) | G14: =IF(F14="","",IF(F14<0.05,"ผ่าน ✓","ไม่ผ่าน ✗"))
A15: 7 | F15: =IF(OR(D15="",E15=""),"",IFERROR(ABS(E15-D15)/D15,"")) | G15: =IF(F15="","",IF(F15<0.05,"ผ่าน ✓","ไม่ผ่าน ✗"))
A16: ค่าเฉลี่ย / สรุปผล | F16: =IFERROR(AVERAGE(F9:F15),"") | G16: =IF(COUNT(F9:F15)=0,"รอข้อมูล",IF(F16<0.05,"ผ่าน ✓","ไม่ผ่าน ✗")) -> รอข้อมูล
A18: ตารางที่ 2: การข้ามธรณีประตู/สิ่งกีดขวาง (ต้องพับเสากล้องก่อนทดสอบ)
A19: Trial | B19: ความสูงสิ่งกีดขวาง (mm) | C19: ข้ามผ่านได้ (Y/N) | G19: หมายเหตุ
A20: ตัวอย่าง | B20: 8 | C20: Y | G20: พรมบาง
A21: 1
A22: 2
A23: 3
A24: 4
A25: 5
A26: 6
A27: 7
A28: ความสูงสูงสุดที่ข้ามผ่านได้ (mm) | C28: =IFERROR(SUMPRODUCT(MAX((C21:C27="Y")*B21:B27)),"") -> 0
A30: ตารางที่ 3: กระแสมอเตอร์ขับ (เกณฑ์ผ่าน: stall ตัดไฟภายใน ≤3 วินาที)
A31: Trial | B31: กระแสวิ่งปกติ (A) | C31: กระแส Stall (A) | D31: เวลาก่อนตัดไฟป้องกัน (s) | G31: ผ่าน
A32: ตัวอย่าง | B32: 0.6 | C32: 1.8 | D32: 1.5 | G32: =IF(D32="","",IF(D32<=3,"ผ่าน ✓","ไม่ผ่าน ✗")) -> ผ่าน ✓
A33: 1 | G33: =IF(D33="","",IF(D33<=3,"ผ่าน ✓","ไม่ผ่าน ✗"))
A34: 2 | G34: =IF(D34="","",IF(D34<=3,"ผ่าน ✓","ไม่ผ่าน ✗"))
A35: 3 | G35: =IF(D35="","",IF(D35<=3,"ผ่าน ✓","ไม่ผ่าน ✗"))
A36: 4 | G36: =IF(D36="","",IF(D36<=3,"ผ่าน ✓","ไม่ผ่าน ✗"))
A37: 5 | G37: =IF(D37="","",IF(D37<=3,"ผ่าน ✓","ไม่ผ่าน ✗"))
A38: 6 | G38: =IF(D38="","",IF(D38<=3,"ผ่าน ✓","ไม่ผ่าน ✗"))
A39: 7 | G39: =IF(D39="","",IF(D39<=3,"ผ่าน ✓","ไม่ผ่าน ✗"))
A40: สรุปผล | G40: =IF(COUNT(D33:D39)=0,"รอข้อมูล",IF(COUNTIF(G33:G39,"ไม่ผ่าน*")=0,"ผ่าน ✓","ไม่ผ่าน ✗")) -> รอข้อมูล
A42: ตารางที่ 4: การตอบสนองเซนเซอร์กันตก (Cliff) / กันชน (Bumper)
A43: Trial | B43: ชนิดเซนเซอร์ | C43: ตำแหน่งทดสอบ | D43: ตอบสนองถูกต้อง (Y/N) | E43: เวลาตอบสนอง (ms) | G43: หมายเหตุ
A44: ตัวอย่าง | B44: Cliff (IR) | C44: ขอบโต๊ะจำลอง | D44: Y | E44: 120 | G44: หยุดก่อนขอบ 4 cm
A45: 1
...

Sheet 1.3 การปัดกวาด
A1: 1.3 การทดสอบกลไกปัดกวาด (Cleaning Test)
A3: ข้อมูลการทดสอบ
A4: วันที่ทดสอบ: | C4: ผู้ทดสอบ:
A6: ตารางที่ 1: ประสิทธิภาพเก็บเศษ (เกณฑ์ผ่าน ≥80% เมื่อทดสอบโหมด แปรง+ดูด)
A7: Trial | B7: พื้นผิว | C7: ชนิดเศษวัสดุ | D7: โหมดทดสอบ (แปรงอย่างเดียว / แปรง+ดูด) | E7: น้ำหนักก่อน (g) | F7: น้ำหนักเศษเหลือ (g) | G7: % เก็บได้ | H7: ผ่าน
A8: ตัวอย่าง | B8: กระเบื้อง | C8: เศษกระดาษ+ฝุ่น | D8: แปรง+ดูด | E8: 25 | F8: 3 | G8: =IF(OR(E8="",F8=""),"",IFERROR((E8-F8)/E8,"")) -> 0.88 | H8: =IF(G8="","",IF(D8="แปรง+ดูด",IF(G8>=0.8,"ผ่าน ✓","ไม่ผ่าน ✗"),"อ้างอิง")) -> ผ่าน ✓
A9: 1 | G9: =IF(OR(E9="",F9=""),"",IFERROR((E9-F9)/E9,"")) | H9: =IF(G9="","",IF(D9="แปรง+ดูด",IF(G9>=0.8,"ผ่าน ✓","ไม่ผ่าน ✗"),"อ้างอิง"))
A10: 2 | G10: =IF(OR(E10="",F10=""),"",IFERROR((E10-F10)/E10,"")) | H10: =IF(G10="","",IF(D10="แปรง+ดูด",IF(G10>=0.8,"ผ่าน ✓","ไม่ผ่าน ✗"),"อ้างอิง"))
A11: 3 | G11: =IF(OR(E11="",F11=""),"",IFERROR((E11-F11)/E11,"")) | H11: =IF(G11="","",IF(D11="แปรง+ดูด",IF(G11>=0.8,"ผ่าน ✓","ไม่ผ่าน ✗"),"อ้างอิง"))
A12: 4 | G12: =IF(OR(E12="",F12=""),"",IFERROR((E12-F12)/E12,"")) | H12: =IF(G12="","",IF(D12="แปรง+ดูด",IF(G12>=0.8,"ผ่าน ✓","ไม่ผ่าน ✗"),"อ้างอิง"))
A13: 5 | G13: =IF(OR(E13="",F13=""),"",IFERROR((E13-F13)/E13,"")) | H13: =IF(G13="","",IF(D13="แปรง+ดูด",IF(G13>=0.8,"ผ่าน ✓","ไม่ผ่าน ✗"),"อ้างอิง"))
A14: 6 | G14: =IF(OR(E14="",F14=""),"",IFERROR((E14-F14)/E14,"")) | H14: =IF(G14="","",IF(D14="แปรง+ดูด",IF(G14>=0.8,"ผ่าน ✓","ไม่ผ่าน ✗"),"อ้างอิง"))
A15: 7 | G15: =IF(OR(E15="",F15=""),"",IFERROR((E15-F15)/E15,"")) | H15: =IF(G15="","",IF(D15="แปรง+ดูด",IF(G15>=0.8,"ผ่าน ✓","ไม่ผ่าน ✗"),"อ้างอิง"))
A16: 8 | G16: =IF(OR(E16="",F16=""),"",IFERROR((E16-F16)/E16,"")) | H16: =IF(G16="","",IF(D16="แปรง+ดูด",IF(G16>=0.8,"ผ่าน ✓","ไม่ผ่าน ✗"),"อ้างอิง"))
A17: 9 | G17: =IF(OR(E17="",F17=""),"",IFERROR((E17-F17)/E17,"")) | H17: =IF(G17="","",IF(D17="แปรง+ดูด",IF(G17>=0.8,"ผ่าน ✓","ไม่ผ่าน ✗"),"อ้างอิง"))
A18: 10 | G18: =IF(OR(E18="",F18=""),"",IFERROR((E18-F18)/E18,"")) | H18: =IF(G18="","",IF(D18="แปรง+ดูด",IF(G18>=0.8,"ผ่าน ✓","ไม่ผ่าน ✗"),"อ้างอิง"))
A19: ค่าเฉลี่ย / สรุปผล | G19: =IFERROR(AVERAGE(G9:G18),"") | H19: =IF(COUNT(G9:G18)=0,"รอข้อมูล",IF(COUNTIF(H9:H18,"ไม่ผ่าน*")=0,"ผ่าน ✓","ไม่ผ่าน ✗")) -> รอข้อมูล

Sheet 1.4 Scissor Lift
A1: 1.4 การทดสอบกลไก Scissor Lift ยกกล้อง (MRC-001)
A3: ข้อมูลการทดสอบ (อ้างอิง scissor_lift/README.md)
A4: วันที่ทดสอบ: | C4: ผู้ทดสอบ:
A5: เซอร์โวที่ใช้: | B5: MG996R
A7: ตารางที่ 1: เวลายก/พับ (เป้าหมาย 3.0 s, เกณฑ์ผ่าน ±0.5 s)
A8: Trial | B8: ทิศทาง (ยก/พับ) | C8: เวลาที่วัดได้ (s) | D8: เป้าหมาย (s) | E8: ส่วนต่าง (s) | F8: ผ่าน
A9: ตัวอย่าง | B9: ยก | C9: 3.2 | D9: 3 | E9: =IF(C9="","",ABS(C9-D9)) -> 0.2 | F9: =IF(E9="","",IF(E9<=0.5,"ผ่าน ✓","ไม่ผ่าน ✗")) -> ผ่าน ✓
A10: 1 | D10: 3 | E10: =IF(C10="","",ABS(C10-D10)) | F10: =IF(E10="","",IF(E10<=0.5,"ผ่าน ✓","ไม่ผ่าน ✗"))
A11: 2 | D11: 3 | E11: =IF(C11="","",ABS(C11-D11)) | F11: =IF(E11="","",IF(E11<=0.5,"ผ่าน ✓","ไม่ผ่าน ✗"))
A12: 3 | D12: 3 | E12: =IF(C12="","",ABS(C12-D12)) | F12: =IF(E12="","",IF(E12<=0.5,"ผ่าน ✓","ไม่ผ่าน ✗"))
A13: 4 | D13: 3 | E13: =IF(C13="","",ABS(C13-D13)) | F13: =IF(E13="","",IF(E13<=0.5,"ผ่าน ✓","ไม่ผ่าน ✗"))
A14: 5 | D14: 3 | E14: =IF(C14="","",ABS(C14-D14)) | F14: =IF(E14="","",IF(E14<=0.5,"ผ่าน ✓","ไม่ผ่าน ✗"))
A15: 6 | D15: 3 | E15: =IF(C15="","",ABS(C15-D15)) | F15: =IF(E15="","",IF(E15<=0.5,"ผ่าน ✓","ไม่ผ่าน ✗"))
A16: 7 | D16: 3 | E16: =IF(C16="","",ABS(C16-D16)) | F16: =IF(E16="","",IF(E16<=0.5,"ผ่าน ✓","ไม่ผ่าน ✗"))
A17: สรุปผล | F17: =IF(COUNT(C10:C16)=0,"รอข้อมูล",IF(COUNTIF(F10:F16,"ไม่ผ่าน*")=0,"ผ่าน ✓","ไม่ผ่าน ✗")) -> รอข้อมูล
A19: ตารางที่ 2: กระแสเซอร์โวพีค (ค่าคำนวณอ้างอิง 0.91 A @ 6V, เกณฑ์ผ่าน ≤ อ้างอิง+20%)
A20: Trial | B20: กระแสพีคที่วัดได้ (A) | C20: ค่าคำนวณอ้างอิง (A) | F20: ผ่าน
A21: ตัวอย่าง | B21: 0.95 | C21: 0.91 | F21: =IF(B21="","",IF(B21<=C21*1.2,"ผ่าน ✓","ไม่ผ่าน ✗")) -> ผ่าน ✓
A22: 1 | C22: 0.91 | F22: =IF(B22="","",IF(B22<=C22*1.2,"ผ่าน ✓","ไม่ผ่าน ✗"))
A23: 2 | C23: 0.91 | F23: =IF(B23="","",IF(B23<=C23*1.2,"ผ่าน ✓","ไม่ผ่าน ✗"))
A24: 3 | C24: 0.91 | F24: =IF(B24="","",IF(B24<=C24*1.2,"ผ่าน ✓","ไม่ผ่าน ✗"))
A25: 4 | C25: 0.91 | F25: =IF(B25="","",IF(B25<=C25*1.2,"ผ่าน ✓","ไม่ผ่าน ✗"))
A26: 5 | C26: 0.91 | F26: =IF(B26="","",IF(B26<=C26*1.2,"ผ่าน ✓","ไม่ผ่าน ✗"))
A27: 6 | C27: 0.91 | F27: =IF(B27="","",IF(B27<=C27*1.2,"ผ่าน ✓","ไม่ผ่าน ✗"))
A28: 7 | C28: 0.91 | F28: =IF(B28="","",IF(B28<=C28*1.2,"ผ่าน ✓","ไม่ผ่าน ✗"))
A29: สรุปผล | F29: =IF(COUNT(B22:B28)=0,"รอข้อมูล",IF(COUNTIF(F22:F28,"ไม่ผ่าน*")=0,"ผ่าน ✓","ไม่ผ่าน ✗")) -> รอข้อมูล
A31: ตารางที่ 3: การแกว่งปลายเสาตอนยกสุด (ค่าคำนวณอ้างอิง ±9.3 mm — ความเสี่ยงอันดับ 1)
A32: Trial | B32: ระยะแกว่งที่วัดได้ (mm) | C32: ค่าคำนวณอ้างอิง (mm) | F32: ผ่าน
A33: ตัวอย่าง | B33: 8.5 | C33: 9.3 | F33: =IF(B33="","",IF(B33<=C33,"ผ่าน ✓","ไม่ผ่าน ✗")) -> ผ่าน ✓
A34: 1 | C34: 9.3 | F34: =IF(B34="","",IF(B34<=C34,"ผ่าน ✓","ไม่ผ่าน ✗"))
A35: 2 | C35: 9.3 | F35: =IF(B35="","",IF(B35<=C35,"ผ่าน ✓","ไม่ผ่าน ✗"))
A36: 3 | C36: 9.3 | F36: =IF(B36="","",IF(B36<=C36,"ผ่าน ✓","ไม่ผ่าน ✗"))
A37: 4 | C37: 9.3 | F37: =IF(B37="","",IF(B37<=C37,"ผ่าน ✓","ไม่ผ่าน ✗"))
A38: 5 | C38: 9.3 | F38: =IF(B38="","",IF(B38<=C38,"ผ่าน ✓","ไม่ผ่าน ✗"))
A39: 6 | C39: 9.3 | F39: =IF(B39="","",IF(B39<=C39,"ผ่าน ✓","ไม่ผ่าน ✗"))
A40: 7 | C40: 9.3 | F40: =IF(B40="","",IF(B40<=C40,"ผ่าน ✓","ไม่ผ่าน ✗"))
A41: ค่าเฉลี่ย | B41: =IFERROR(AVERAGE(B34:B40),"") | F41: =IF(COUNT(B34:B40)=0,"รอข้อมูล",IF(COUNTIF(F34:F40,"ไม่ผ่าน*")=0,"ผ่าน ✓","ไม่ผ่าน ✗")) -> รอข้อมูล
A43: ตารางที่ 4: Repeatability (ยก-พับซ้ำ วัดตำแหน่งปลายสุด)
A44: Trial | B44: ตำแหน่งปลายสุด แนวนอน X (mm) | C44: ตำแหน่งปลายสุด แนวตั้ง Z (mm) | F44: หมายเหตุ
A45: ตัวอย่าง | B45: 0.3 | C45: 499.1 | F45: รอบที่ 1
...

Sheet 1.5 ทดสอบรวมระบบ
A1: 1.5 การทดสอบรวมทั้งระบบ (System Integration Test)
A3: ข้อมูลการทดสอบ
A4: วันที่ทดสอบ: | C4: ผู้ทดสอบ:
A6: ตารางที่ 1: งบพลังงาน (Power Budget) ต่อโหมดการทำงาน
A7: โหมดการทำงาน | B7: กระแสที่วัดได้ (A) | C7: แรงดัน (V) | D7: กำลังไฟ (W) | E7: หมายเหตุ
A8: Standby (Pi5+ESP32 เท่านั้น) | C8: 14.8 | D8: =IF(B8="","",IFERROR(B8*C8,""))
A9: วิ่งเปล่า (มอเตอร์ขับเท่านั้น) | C9: 14.8 | D9: =IF(B9="","",IFERROR(B9*C9,""))
A10: ทำความสะอาดเต็มระบบ (ขับ+ดูด+แปรง) | C10: 14.8 | D10: =IF(B10="","",IFERROR(B10*C10,""))
A11: ยก/พับกล้อง (เซอร์โว) | C11: 14.8 | D11: =IF(B11="","",IFERROR(B11*C11,""))
A12: Worst-case พร้อมกันทุกระบบ | C12: 14.8 | D12: =IF(B12="","",IFERROR(B12*C12,""))
A14: ประมาณการเวลาใช้งานต่อการชาร์จ 1 ครั้ง (Runtime Estimate)
A15: ความจุแบตเตอรี่รวม (mAh):
A16: แรงดันแบตเตอรี่ ระบุ (V, 4S=14.8): | B16: 14.8
A17: พลังงานรวมที่ใช้ได้ (Wh): | B17: =IF(B15="","",IFERROR(B15/1000*B16,""))
A18: เวลาใช้งานประมาณ กรณี Worst-case (ชม.): | B18: =IFERROR(B17/D12,"")
A20: ตารางที่ 2: Checklist กติกาความปลอดภัย (ต้องบังคับใช้ในเฟิร์มแวร์ทุกข้อ)
A21: ข้อ | B21: กติกาความปลอดภัย | C21: ผ่าน (Y/N) | E21: หมายเหตุ
A22: 1 | B22: ห้ามยกเสาขณะหุ่นเคลื่อนที่ — สั่งยกเมื่อ v = 0 เท่านั้น
A23: 2 | B23: ขณะเสายกอยู่ จำกัดความเร่ง/เบรก ≤ 4.9 m/s²
A24: 3 | B24: ขณะเสายกอยู่ จำกัดความเร็วหมุนตัว (แรงหนีศูนย์ ω²r)
A25: 4 | B25: ต้องพับเสาก่อนขึ้น/ลงธรณีประตูหรือพรมหนา
A26: 5 | B26: ถ่ายภาพ/สแกนหลังหุ่นหยุดนิ่งแล้ว 1-2 วินาที
A27: 6 | B27: ถึงตำแหน่งแล้ว detach PWM (จุดศูนย์ตายล็อกให้อยู่แล้ว)
A28: สรุปผล | C28: =IF(COUNTA(C22:C27)=0,"รอข้อมูล",IF(COUNTIF(C22:C27,"N")=0,"ผ่าน ✓","ไม่ผ่าน ✗")) -> รอข้อมูล
A30: ตารางที่ 3: ทดสอบความทนทาน (Endurance Test)
A31: วันที่ | B31: เวลาเริ่ม | C31: เวลาสิ้นสุด (แบตหมด) | D31: ระยะเวลารวม (นาที) | E31: หมายเหตุ (อุณหภูมิมอเตอร์/buck สูงสุด)
D32: =IFERROR((C32-B32)*24*60,"") -> 0
D33: =IFERROR((C33-B33)*24*60,"") -> 0
D34: =IFERROR((C34-B34)*24*60,"") -> 0
A35: ระยะเวลาเฉลี่ยที่วิ่งได้จริง (นาที) | D35: =IFERROR(AVERAGE(D32:D34),"") -> 0
A37: ตารางที่ 4: ทดสอบความปลอดภัยเซนเซอร์ (สรุปจากภาพรวม 1.2)
A38: รายการ | B38: ผ่าน (Y/N) | E38: หมายเหตุ
A39: Cliff sensor หยุดหุ่นก่อนตกจริงทุกครั้ง
A40: Bumper ตอบสนองไวพอ ก่อนกระแทกแรง

Sheet สรุปผลรวม
A1: สรุปผลรวมการทดสอบทุกหัวข้อ (Test Summary Dashboard)
A2: ดึงข้อมูลอัตโนมัติจากทุกแท็บ — กรอกข้อมูลในแท็บย่อยก่อน ตัวเลขที่นี่จะอัปเดตเอง
A4: หัวข้อ 1: ทดสอบประสิทธิภาพอุปกรณ์
A5: หัวข้อการทดสอบ | B5: ตัวชี้วัดหลัก | C5: ผลลัพธ์ | D5: สถานะ | E5: หมายเหตุ
A6: 1.1 มอเตอร์ดูดฝุ่น | B6: % เก็บฝุ่นเฉลี่ย (เกณฑ์ ≥80%) | C6: ='1.1 มอเตอร์ดูด'!F29 | D6: ='1.1 มอเตอร์ดูด'!G29 -> รอข้อมูล
A7: 1.2 การขับเคลื่อน — Odometry | B7: %Error เฉลี่ย (เกณฑ์ <5%) | C7: ='1.2 การขับเคลื่อน'!F16 | D7: ='1.2 การขับเคลื่อน'!G16 -> รอข้อมูล
A8: 1.2 การขับเคลื่อน — ข้ามสิ่งกีดขวาง | B8: ความสูงสูงสุดที่ข้ามผ่านได้ (mm) | C8: ='1.2 การขับเคลื่อน'!C28 -> 0 | D8: ="ข้อมูลอ้างอิง" -> ข้อมูลอ้างอิง | E8: ไม่มีเกณฑ์ผ่าน/ไม่ผ่านตายตัว — ใช้เป็นสเปกอ้างอิง
A9: 1.2 การขับเคลื่อน — กระแส Stall | B9: ตัดไฟป้องกันภายใน ≤3s ทุกครั้ง | C9: ="-" -> - | D9: ='1.2 การขับเคลื่อน'!G40 -> รอข้อมูล
A10: 1.2 การขับเคลื่อน — เซนเซอร์ | B10: Cliff/Bumper ตอบสนองถูกต้องทุกครั้ง | C10: ="-" -> - | D10: ='1.2 การขับเคลื่อน'!D52 -> รอข้อมูล
A11: 1.3 การปัดกวาด | B11: % เก็บเศษเฉลี่ย โหมดแปรง+ดูด (เกณฑ์ ≥80%) | C11: ='1.3 การปัดกวาด'!G19 | D11: ='1.3 การปัดกวาด'!H19 -> รอข้อมูล
A12: 1.4 Scissor Lift — เวลายก/พับ | B12: อยู่ในเกณฑ์ 3.0±0.5s ทุกครั้ง | C12: ="-" -> - | D12: ='1.4 Scissor Lift'!F17 -> รอข้อมูล
A13: 1.4 Scissor Lift — กระแสเซอร์โว | B13: ไม่เกินค่าอ้างอิง+20% ทุกครั้ง | C13: ="-" -> - | D13: ='1.4 Scissor Lift'!F29 -> รอข้อมูล
A14: 1.4 Scissor Lift — การแกว่งปลายเสา ⚠ | B14: ค่าเฉลี่ยที่วัดได้ (mm) เทียบ ±9.3mm | C14: ='1.4 Scissor Lift'!B41 | D14: ='1.4 Scissor Lift'!F41 -> รอข้อมูล | E14: ความเสี่ยงอันดับ 1 ตามรายงานเดิม — ให้ความสำคัญเป็นพิเศษ
A15: 1.4 Scissor Lift — Repeatability | B15: Std Dev ตำแหน่ง X (mm) | C15: ='1.4 Scissor Lift'!B61 | D15: ="ข้อมูลอ้างอิง" -> ข้อมูลอ้างอิง | E15: ยิ่งน้อยยิ่งดี ไม่มีเกณฑ์ตายตัว
A16: 1.4 Scissor Lift — Self-lock | B16: ไม่เคลื่อนตำแหน่งเมื่อตัด PWM ทุกครั้ง | C16: ="-" -> - | D16: ='1.4 Scissor Lift'!F71 -> รอข้อมูล
A17: 1.4 Scissor Lift — เวลานิ่งก่อนถ่ายภาพ | B17: อยู่ในเกณฑ์ ≤2s ทุกครั้ง | C17: ="-" -> - | D17: ='1.4 Scissor Lift'!F83 -> รอข้อมูล
A19: หัวข้อ 1.5: ทดสอบรวมระบบ
A20: หัวข้อการทดสอบ | B20: ตัวชี้วัดหลัก | C20: ผลลัพธ์ | D20: สถานะ | E20: หมายเหตุ
A21: Power Budget | B21: กำลังไฟรวม Worst-case (W) | C21: ='1.5 ทดสอบรวมระบบ'!D12 | D21: ="ข้อมูลอ้างอิง" -> ข้อมูลอ้างอิง
A22: Runtime Estimate | B22: เวลาใช้งานประมาณต่อชาร์จ (ชม.) | C22: ='1.5 ทดสอบรวมระบบ'!B18 | D22: ="ข้อมูลอ้างอิง" -> ข้อมูลอ้างอิง | E22: เทียบกับ Endurance test ที่วัดได้จริงด้านล่าง
A23: Mission/Safety Checklist | B23: กติกาความปลอดภัยทั้ง 6 ข้อผ่านทุกข้อ | C23: ="-" -> - | D23: ='1.5 ทดสอบรวมระบบ'!C28 -> รอข้อมูล
A24: Endurance Test | B24: ระยะเวลาที่วิ่งได้จริงเฉลี่ย (นาที) | C24: ='1.5 ทดสอบรวมระบบ'!D35 -> 0 | D24: ="ข้อมูลอ้างอิง" -> ข้อมูลอ้างอิง
A26: ความพร้อมโดยรวม
A27: สถานะรวมของหัวข้อที่มีเกณฑ์ผ่าน/ไม่ผ่านชัดเจน: | C27: =IF(COUNTIF(D6:D23,"รอข้อมูล")>0,"⏳ ยังทดสอบไม่ครบ ("&COUNTIF(D6:D23,"รอข้อมูล")&" หัวข้อรอข้อมูล)",IF(COUNTIF(D6:D23,"ไม่ผ่าน*")=0,"✓ ผ่านครบทุกหัวข้อ พร้อมสำหรับขั้นถัดไป","✗ มี "&COUNTIF(D6:D23,"ไม่ผ่าน*")&" หัวข้อที่ยังไม่ผ่าน ต้องแก้ก่อน")) -> ⏳ ยังทดสอบไม่ครบ (11 หัวข้อรอข้อมูล)
